Workbook

Sheet How_to_use
A1: ATPL Vector — Coverage Tracker
A2: Single source of truth for ECQB 2026 ATPL(A) coverage
A4: 1. What this is
A5: The canonical inventory of every Learning Objective (LO) in scope for ATPL(A).
A6: Built from the EASA TK Syllabus Comparison Document v6 (ECQB 2026), filtered to ATPL(A) only.
A7: Helicopter-only subjects (034, 082) and helicopter-only LOs in other subjects are excluded.
A8: Total in-scope leaf LOs: 4,045 (415 BK-only, 110 affected by ECQB 2026 changes).
A10: 2. The 5-level hierarchy
A11: Level 1: subject e.g. 010.00.00.00 AIR LAW
A12: Level 2: section e.g. 010.01.00.00 INTERNATIONAL LAW: CONVENTIONS, AGREEMENTS...
A13: Level 3: subsection e.g. 010.01.01.00 The Convention on International Civil Aviation...
A14: Level 4: topic e.g. 010.01.01.01 Establishment of the Chicago Convention
... A53: ECQB Update January 2026 PDF (notable developments §2).

Sheet Dashboard
A1: ATPL Vector — Coverage Tracker
A2: Single source of truth for ECQB 2026 ATPL(A) coverage. Filter / sort to plan next batches.
A4: Status legend
A5: NOT_STARTED | B5: No content yet on platform
A6: IN_PROGRESS | B6: Agent assigned, draft underway
A7: DRAFT_DONE | B7: Text exists, no visual/interactive yet
A8: VISUAL_DONE | B8: Has visual/diagram, no interactive
A9: INTERACTIVE_DONE | B9: Full interactive component built
A10: REVIEWED | B10: Content + visual + accuracy review passed
A11: NEEDS_UPDATE | B11: Content exists but ECQB 2026 says update needed
A12: OUT_OF_SCOPE | B12: Not required for ATPL(A) — skip
A14: Subject rollup
A15: Subject | B15: Name | C15: Leaf LOs | D15: BK-only | E15: ECQB 2026 | F15: NOT_STARTED | G15: IN_PROGRESS | H15: DRAFT_DONE | I15: VISUAL_DONE | J15: INTERACTIVE_DONE | K15: REVIEWED | L15: NEEDS_UPDATE | M15: % Done
A16: 010 | B16: Air Law and ATC Procedures | C16: 505 | D16: 55 | E16: 3 | F16: =COUNTIF('S010'!$K$4:$K$2000,"NOT_STARTED") | G16: =COUNTIF('S010'!$K$4:$K$2000,"IN_PROGRESS") | H16: =COUNTIF('S010'!$K$4:$K$2000,"DRAFT_DONE") | I16: =COUNTIF('S010'!$K$4:$K$2000,"VISUAL_DONE") | J16: =COUNTIF('S010'!$K$4:$K$2000,"INTERACTIVE_DONE") | K16: =COUNTIF('S010'!$K$4:$K$2000,"REVIEWED") | L16: =COUNTIF('S010'!$K$4:$K$2000,"NEEDS_UPDATE") | M16: =IFERROR((K16+J16)/C16,0)
A17: 021 | B17: Aircraft General Knowledge — Airframe, Systems, Powerplant | C17: 509 | D17: 26 | E17: 0 | F17: =COUNTIF('S021'!$K$4:$K$2000,"NOT_STARTED") | G17: =COUNTIF('S021'!$K$4:$K$2000,"IN_PROGRESS") | H17: =COUNTIF('S021'!$K$4:$K$2000,"DRAFT_DONE") | I17: =COUNTIF('S021'!$K$4:$K$2000,"VISUAL_DONE") | J17: =COUNTIF('S021'!$K$4:$K$2000,"INTERACTIVE_DONE") | K17: =COUNTIF('S021'!$K$4:$K$2000,"REVIEWED") | L17: =COUNTIF('S021'!$K$4:$K$2000,"NEEDS_UPDATE") | M17: =IFERROR((K17+J17)/C17,0)
A18: 022 | B18: Aircraft General Knowledge — Instrumentation | C18: 409 | D18: 30 | E18: 0 | F18: =COUNTIF('S022'!$K$4:$K$2000,"NOT_STARTED") | G18: =COUNTIF('S022'!$K$4:$K$2000,"IN_PROGRESS") | H18: =COUNTIF('S022'!$K$4:$K$2000,"DRAFT_DONE") | I18: =COUNTIF('S022'!$K$4:$K$2000,"VISUAL_DONE") | J18: =COUNTIF('S022'!$K$4:$K$2000,"INTERACTIVE_DONE") | K18: =COUNTIF('S022'!$K$4:$K$2000,"REVIEWED") | L18: =COUNTIF('S022'!$K$4:$K$2000,"NEEDS_UPDATE") | M18: =IFERROR((K18+J18)/C18,0)
A19: 031 | B19: Mass and Balance | C19: 84 | D19: 27 | E19: 13 | F19: =COUNTIF('S031'!$K$4:$K$2000,"NOT_STARTED") | G19: =COUNTIF('S031'!$K$4:$K$2000,"IN_PROGRESS") | H19: =COUNTIF('S031'!$K$4:$K$2000,"DRAFT_DONE") | I19: =COUNTIF('S031'!$K$4:$K$2000,"VISUAL_DONE") | J19: =COUNTIF('S031'!$K$4:$K$2000,"INTERACTIVE_DONE") | K19: =COUNTIF('S031'!$K$4:$K$2000,"REVIEWED") | L19: =COUNTIF('S031'!$K$4:$K$2000,"NEEDS_UPDATE") | M19: =IFERROR((K19+J19)/C19,0)
A20: 032 | B20: Performance — Aeroplanes | C20: 241 | D20: 32 | E20: 9 | F20: =COUNTIF('S032'!$K$4:$K$2000,"NOT_STARTED") | G20: =COUNTIF('S032'!$K$4:$K$2000,"IN_PROGRESS") | H20: =COUNTIF('S032'!$K$4:$K$2000,"DRAFT_DONE") | I20: =COUNTIF('S032'!$K$4:$K$2000,"VISUAL_DONE") | J20: =COUNTIF('S032'!$K$4:$K$2000,"INTERACTIVE_DONE") | K20: =COUNTIF('S032'!$K$4:$K$2000,"REVIEWED") | L20: =COUNTIF('S032'!$K$4:$K$2000,"NEEDS_UPDATE") | M20: =IFERROR((K20+J20)/C20,0)
A21: 033 | B21: Flight Planning and Monitoring | C21: 118 | D21: 9 | E21: 47 | F21: =COUNTIF('S033'!$K$4:$K$2000,"NOT_STARTED") | G21: =COUNTIF('S033'!$K$4:$K$2000,"IN_PROGRESS") | H21: =COUNTIF('S033'!$K$4:$K$2000,"DRAFT_DONE") | I21: =COUNTIF('S033'!$K$4:$K$2000,"VISUAL_DONE") | J21: =COUNTIF('S033'!$K$4:$K$2000,"INTERACTIVE_DONE") | K21: =COUNTIF('S033'!$K$4:$K$2000,"REVIEWED") | L21: =COUNTIF('S033'!$K$4:$K$2000,"NEEDS_UPDATE") | M21: =IFERROR((K21+J21)/C21,0)
A22: 040 | B22: Human Performance and Limitations | C22: 362 | D22: 0 | E22: 0 | F22: =COUNTIF('S040'!$K$4:$K$2000,"NOT_STARTED") | G22: =COUNTIF('S040'!$K$4:$K$2000,"IN_PROGRESS") | H22: =COUNTIF('S040'!$K$4:$K$2000,"DRAFT_DONE") | I22: =COUNTIF('S040'!$K$4:$K$2000,"VISUAL_DONE") | J22: =COUNTIF('S040'!$K$4:$K$2000,"INTERACTIVE_DONE") | K22: =COUNTIF('S040'!$K$4:$K$2000,"REVIEWED") | L22: =COUNTIF('S040'!$K$4:$K$2000,"NEEDS_UPDATE") | M22: =IFERROR((K22+J22)/C22,0)
A23: 050 | B23: Meteorology | C23: 464 | D23: 15 | E23: 5 | F23: =COUNTIF('S050'!$K$4:$K$2000,"NOT_STARTED") | G23: =COUNTIF('S050'!$K$4:$K$2000,"IN_PROGRESS") | H23: =COUNTIF('S050'!$K$4:$K$2000,"DRAFT_DONE") | I23: =COUNTIF('S050'!$K$4:$K$2000,"VISUAL_DONE") | J23: =COUNTIF('S050'!$K$4:$K$2000,"INTERACTIVE_DONE") | K23: =COUNTIF('S050'!$K$4:$K$2000,"REVIEWED") | L23: =COUNTIF('S050'!$K$4:$K$2000,"NEEDS_UPDATE") | M23: =IFERROR((K23+J23)/C23,0)
A24: 061 | B24: General Navigation | C24: 117 | D24: 24 | E24: 0 | F24: =COUNTIF('S061'!$K$4:$K$2000,"NOT_STARTED") | G24: =COUNTIF('S061'!$K$4:$K$2000,"IN_PROGRESS") | H24: =COUNTIF('S061'!$K$4:$K$2000,"DRAFT_DONE") | I24: =COUNTIF('S061'!$K$4:$K$2000,"VISUAL_DONE") | J24: =COUNTIF('S061'!$K$4:$K$2000,"INTERACTIVE_DONE") | K24: =COUNTIF('S061'!$K$4:$K$2000,"REVIEWED") | L24: =COUNTIF('S061'!$K$4:$K$2000,"NEEDS_UPDATE") | M24: =IFERROR((K24+J24)/C24,0)
A25: 062 | B25: Radio Navigation | C25: 322 | D25: 101 | E25: 0 | F25: =COUNTIF('S062'!$K$4:$K$2000,"NOT_STARTED") | G25: =COUNTIF('S062'!$K$4:$K$2000,"IN_PROGRESS") | H25: =COUNTIF('S062'!$K$4:$K$2000,"DRAFT_DONE") | I25: =COUNTIF('S062'!$K$4:$K$2000,"VISUAL_DONE") | J25: =COUNTIF('S062'!$K$4:$K$2000,"INTERACTIVE_DONE") | K25: =COUNTIF('S062'!$K$4:$K$2000,"REVIEWED") | L25: =COUNTIF('S062'!$K$4:$K$2000,"NEEDS_UPDATE") | M25: =IFERROR((K25+J25)/C25,0)
A26: 070 | B26: Operational Procedures | C26: 346 | D26: 2 | E26: 33 | F26: =COUNTIF('S070'!$K$4:$K$2000,"NOT_STARTED") | G26: =COUNTIF('S070'!$K$4:$K$2000,"IN_PROGRESS") | H26: =COUNTIF('S070'!$K$4:$K$2000,"DRAFT_DONE") | I26: =COUNTIF('S070'!$K$4:$K$2000,"VISUAL_DONE") | J26: =COUNTIF('S070'!$K$4:$K$2000,"INTERACTIVE_DONE") | K26: =COUNTIF('S070'!$K$4:$K$2000,"REVIEWED") | L26: =COUNTIF('S070'!$K$4:$K$2000,"NEEDS_UPDATE") | M26: =IFERROR((K26+J26)/C26,0)
A27: 081 | B27: Principles of Flight — Aeroplanes | C27: 489 | D27: 91 | E27: 0 | F27: =COUNTIF('S081'!$K$4:$K$2000,"NOT_STARTED") | G27: =COUNTIF('S081'!$K$4:$K$2000,"IN_PROGRESS") | H27: =COUNTIF('S081'!$K$4:$K$2000,"DRAFT_DONE") | I27: =COUNTIF('S081'!$K$4:$K$2000,"VISUAL_DONE") | J27: =COUNTIF('S081'!$K$4:$K$2000,"INTERACTIVE_DONE") | K27: =COUNTIF('S081'!$K$4:$K$2000,"REVIEWED") | L27: =COUNTIF('S081'!$K$4:$K$2000,"NEEDS_UPDATE") | M27: =IFERROR((K27+J27)/C27,0)
A28: 090 | B28: Communications | C28: 79 | D28: 3 | E28: 0 | F28: =COUNTIF('S090'!$K$4:$K$2000,"NOT_STARTED") | G28: =COUNTIF('S090'!$K$4:$K$2000,"IN_PROGRESS") | H28: =COUNTIF('S090'!$K$4:$K$2000,"DRAFT_DONE") | I28: =COUNTIF('S090'!$K$4:$K$2000,"VISUAL_DONE") | J28: =COUNTIF('S090'!$K$4:$K$2000,"INTERACTIVE_DONE") | K28: =COUNTIF('S090'!$K$4:$K$2000,"REVIEWED") | L28: =COUNTIF('S090'!$K$4:$K$2000,"NEEDS_UPDATE") | M28: =IFERROR((K28+J28)/C28,0)
A29: TOTAL | C29: =SUM(C16:C28) | D29: =SUM(D16:D28) | E29: =SUM(E16:E28) | F29: =SUM(F16:F28) | G29: =SUM(G16:G28) | H29: =SUM(H16:H28) | I29: =SUM(I16:I28) | J29: =SUM(J16:J28) | ... L29: =SUM(L16:L28) | M29: =IFERROR((K29+J29)/C29,0)

Sheet All_LOs
A1: LO_ID | B1: Subject_Code | C1: Subject_Name | D1: LO_Text | E1: BK_Only | F1: ECQB_2026_Change_Flag | G1: ECQB_2026_Source_Note | H1: Priority | I1: Coverage_Status | J1: Content_Type_Planned | K1: Repo_Path | L1: Last_Updated | M1: Agent_Assigned | N1: Reviewed_By | O1: Notes
A2: 010.01.01.01.01 | B2: 010 | C2: Air Law and ATC Procedures | D2: Explain the circumstances that led to the establishment of the Convention on International Civil Aviation, Chicago, 7 December 1944. | E2: Y | G2: ICAO Doc 7300/9 Preamble | H2: LOW | I2: NOT_STARTED
A3: 010.01.01.02.01 | B3: 010 | C3: Air Law and ATC Procedures | D3: Recall the general contents of relevant parts of the following chapters: general principles and application of the Convention; flight over territory of Contracting States; nationality of aircraft; international standards and recommended practices (SARPs), especially notification of differences and validity of endorsed certificates and licences. | E3: Y | G3: ICAO Doc 7300/9 Part 1, Articles 1, 2, 3, 4, 5, 6, 7, 8, 9, 10, 11, 12, 16, 17, 18, 19, 20, 37, 38, 39, 40 | H3: LOW | I3: NOT_STARTED
A4: 010.01.01.02.02 | B4: 010 | C4: Air Law and ATC Procedures | D4: General principles - Describe the application of the following terms in civil aviation: sovereignty; territory and high seas according to the UN Convention on the High Seas. | E4: Y | G4: Convention on the High Seas (Geneva, 29 April 1958) Articles 1, 2; ICAO Doc 7300/9 Part 1, Articles 1, 2 | H4: LOW | I4: NOT_STARTED
A5: 010.01.01.02.03 | B5: 010 | C5: Air Law and ATC Procedures | D5: Explain the following terms and how they apply to international air traffic: right of non-scheduled flight (including the two technical freedoms of the air); scheduled air services; cabotage; landing at customs airports; Rules of the Air; search of aircraft. | E5: N | G5: ICAO Doc 7300/9, Articles 5, 6, 7, 10, 12, 16 | H5: MED | I5: NOT_STARTED
A6: 010.01.01.02.04 | B6: 010 | C6: Air Law and ATC Procedures | D6: Explain the duties of Contracting States in relation to: documents carried on board the aircraft: certificate of registration; certificates of airworthiness; licences of personnel; recognition of certificates and licences; cargo restrictions; photographic apparatus. | E6: Y | G6: ICAO Doc 7300/9, Articles 29, 31, 32, 33, 35, 36 | H6: LOW | I6: NOT_STARTED
A7: 010.01.01.03.01 | B7: 010 | C7: Air Law and ATC Procedures | D7: Describe the objectives of ICAO. | E7: Y | G7: ICAO Doc 7300/9, Article 44 | H7: LOW | I7: NOT_STARTED
A8: 010.01.01.03.02 | B8: 010 | C8: Air Law and ATC Procedures | D8: Recognise the organisation and duties of the ICAO Assembly, Council and Air Navigation Commission (ANC). | E8: Y | G8: ICAO Doc 7300/9, Articles 48, 49, 50, 54, 56, 57 | H8: LOW | I8: NOT_STARTED
A9: 010.01.01.03.03 | B9: 010 | C9: Air Law and ATC Procedures | D9: Describe the annexes to the Convention. | E9: Y | G9: ICAO Doc 7300/9, Articles 54, 90, 94, 95 | H9: LOW | I9: NOT_STARTED
A10: 010.01.02.01.01 | B10: 010 | C10: Air Law and ATC Procedures | D10: Explain the two technical freedoms of the air. | E10: N | G10: ICAO Doc 7500, Art. 1 | H10: MED | I10: NOT_STARTED
A11: 010.01.02.02.01 | B11: 010 | C11: Air Law and ATC Procedures | D11: Explain the three commercial freedoms of the air. | E11: N | G11: ICAO Doc 9626, Part IV, Chapter 2 'Basic market access' | H11: MED | I11: NOT_STARTED
A12: 010.01.02.03.01 | B12: 010 | C12: Air Law and ATC Procedures | D12: Describe the measures and actions to be taken by the pilot-in-command (PIC) of an aircraft in order to suppress unlawful acts against the safety of the aircraft. | E12: N | G12: ICAO Doc 8364 — Convention on Offences and Certain Other Acts Committed on Board Aircraft, signed in Tokyo on 14 September 1963, Chapter III 'Powers of the Commander' | H12: MED | I12: NOT_STARTED
A13: 010.01.02.05.01 | B13: 010 | C13: Air Law and ATC Procedures | D13: Explain the legal significance of the issue of a passenger ticket or of baggage/cargo documents (that the issue is a form of contract). | E13: N | G13: ICAO Doc 9740 Convention for the Unification of Certain Rules for International Carriage — The Montreal Convention of 1999 | H13: MED | I13: NOT_STARTED
... A17: 010.01.03.01.01 | B17: 010 | C17: Air Law and ATC Procedures | D17: Describe the objectives of IATA. | E17: N | G17: Available via https://www.iata.org/en/about/mission/ | H17: MED | I17: NOT_STARTED
A18: 010.01.04.01.01 | B18: 010 | C18: Air Law and ATC Procedures | D18: Describe the objectives of EASA. | E18: Y | H18: LOW | I18: NOT_STARTED
A19: 010.01.04.01.02 | B19: 010 | C19: Air Law and ATC Procedures | D19: Describe the role of EASA in European civil aviation. | E19: N | H19: MED | I19: NOT_STARTED
A20: 010.01.04.01.03 | B20: 010 | C20: Air Law and ATC Procedures | D20: State that the structure of the regulatory material related to EASA involves: hard law (regulations, delegated acts, implementing acts, and implementing rules); soft law (certification specifications, acceptable means of compliance, and guidance material). | E20: N | G20: See https://www.easa.europa.eu/en/light/topics/easas-regulatory-role-increasing-safety-environmental-protection-and-enabling | H20: MED | I20: NOT_STARTED
A21: 010.01.04.01.04 | B21: 010 | C21: Air Law and ATC Procedures | D21: State the meaning of the terminology associated with the structure of the regulatory material related to EASA, specifically: regulations, delegated acts, implementing acts, and implementing rules, as applicable until 11 September 2023; and certification specifications, acceptable means of compliance, and guidance material. | E21: N | G21: See https://commission.europa.eu/law/law-making-process/adopting-eu-law/implementing-and-delegated-acts_en and https://www.easa.europa.eu/en/light/topics/easas-regulatory-role-increasing-safety-environmental-protection-and-enabling | H21: MED | I21: NOT_STARTED
A22: 010.01.04.02.01 | B22: 010 | C22: Air Law and ATC Procedures | D22: Describe the Single European Sky (SES) regulations. | E22: Y | G22: See https://eur-lex.europa.eu/EN/legal-content/summary/single-european-sky-ses.html | H22: LOW | I22: NOT_STARTED
A23: 010.02.02.01.01 | B23: 010 | C23: Air Law and ATC Procedures | D23: State the issuing authority of a CofA. | E23: N | G23: ICAO Annex 8, Part II, Chapter 3.2 Eligibility, issuance and continued validity of a Certificate of Airworthiness; Reg. (EU) 748/2012, Part-21, 21.B.326; Appendix IV to Part-21. | H23: MED | I23: NOT_STARTED
A24: 010.02.02.01.02 | B24: 010 | C24: Air Law and ATC Procedures | D24: State the necessity to hold a CofA. | E24: N | G24: ICAO Doc 7300, Article 31 | H24: MED | I24: NOT_STARTED
A25: 010.02.02.01.03 | B25: 010 | C25: Air Law and ATC Procedures | D25: Explain the prerequisites for the issue of a CofA according to Commission Regulation (EU) No 748/2012. | E25: Y | G25: Reg. (EU) 748/2012, Part 21, Subpart H | H25: LOW | I25: NOT_STARTED
A26: 010.02.02.01.04 | B26: 010 | C26: Air Law and ATC Procedures | D26: State who shall determine an aircraft’s continuing airworthiness. | E26: N | G26: ICAO Annex 8, Part II, Chapter 3.2 Eligibility, issuance and continued validity of a Certificate of Airworthiness; Reg. (EU) 748/2012, Part-21, 21.B.325; Appendix IV to Part-21 | H26: MED | I26: NOT_STARTED
A27: 010.02.02.01.05 | B27: 010 | C27: Air Law and ATC Procedures | D27: Describe how a CofA can be renewed or may remain valid. | E27: N | G27: Note ICAO Annex 8 refers to renewal, EU Regulation refers to continuing validity. ICAO Annex 8, Part II, Chapter 3.2 Eligibility, issuance and continued validity of a Certificate of Airworthiness; Chapter 3.5 Temporary loss of airworthiness; Chapter 3.6 Damage to aircraft; Reg. (EU) 2018/1139, Arti. 14; Reg. (EU) 748/2012 as amended, Part-21, 21.B.325, 21.B.326; Appendix IV to Part-21 | H27: MED | I27: NOT_STARTED
A28: 010.02.03.01.01 | B28: 010 | C28: Air Law and ATC Procedures | D28: Recall the definition of the following terms: aircraft; heavier-than-air aircraft; State of Registry. | E28: Y | G28: ICAO Annex 7, Chapter 1 Definitions | H28: LOW | I28: NOT_STARTED
A29: 010.02.04.01.01 | B29: 010 | C29: Air Law and ATC Procedures | D29: State the location of nationality marks, common marks and registration marks. | E29: N | G29: ICAO Annex 7, Chapter 4.3 Heavier-than-air aircraft; ICAO Annex 7, Chapter 10 Identification plate | H29: MED | I29: NOT_STARTED
A30: 010.02.04.01.02 | B30: 010 | C30: Air Law and ATC Procedures | D30: Explain who is responsible for assigning nationality marks, common marks and registration marks. | E30: N | G30: ICAO Annex 7, Chapter 3 Nationality, common and registration marks to be used | H30: MED | I30: NOT_STARTED
A31: 010.04.01.01.01 | B31: 010 | C31: Air Law and ATC Procedures | D31: Describe the relationship and differences between ICAO Annex 1 and the Aircrew Regulation. | E31: Y | G31: Note: awareness of the differences in scope, non-ICAO licence/ratings as per the Aircrew Regulation: ICAO Annex 1, 1.2, Note; Reg. (EU) 2018/1139 Art. 2 'Scope'; Reg. (EU) 1178/2011 as amended as amended, Appendix I to Part-ARA licence template | H31: LOW | I31: NOT_STARTED
... A102: 010.06.04.01.05 | B102: 010 | C102: Air Law and ATC Procedures | D102: State the minimum obstacle clearance (MOC) provided by the minimum sector altitudes (MSAs) established for an aerodrome. | E102: N | G102: ICAO Doc 8168, Volume I, Part II, Section 4, Chapter 1, 1.3 Minimum sector altitudes (MSA)/terminal arrival altitudes (TAA) | H102: MED | I102: NOT_STARTED
A103: 010.06.04.01.06 | B103: 010 | C103: Air Law and ATC Procedures | D103: State that a pilot shall apply wind corrections when carrying out an instrument approach procedure. | E103: Y | H103: LOW | I103: NOT_STARTED
A104: 010.06.04.01.07 | B104: 010 | C104: Air Law and ATC Procedures | D104: State the most significant factor influencing the conduct of instrument approach procedures. | E104: N | G104: ICAO Doc 8168, Volume II, Part I, Section 2, Chapter 1 | H104: MED | I104: NOT_STARTED
A105: 010.06.04.01.08 | B105: 010 | C105: Air Law and ATC Procedures | D105: Explain why a pilot should not descend below obstacle clearance altitude/height (OCA/H), which are established for: precision approach procedures; non-precision approach procedures; visual (circling) procedures; APV approach procedures. | E105: N | G105: ICAO Doc 8168, Volume I, Part II, Section 5, Chapter 1, 1.6 Obstacle clearance altitude/height (OCA/H) | H105: MED | I105: NOT_STARTED
A106: 010.06.04.01.09 | B106: 010 | C106: Air Law and ATC Procedures | D106: Describe in general terms the relevant factors for the calculation of operational minima. | E106: N | G106: ICAO Doc 8168, Volume I, Part II Section 5, Chapter 1, 1.7 Factors affecting operational minima | H106: MED | I106: NOT_STARTED
A107: 010.06.04.01.10 | B107: 010 | C107: Air Law and ATC Procedures | D107: State the following acronyms in plain language: DA, DH, OCA, OCH, MDA, MDH, MOC, DA/H, OCA/H, MDA/H. | E107: N | G107: ICAO Doc 8168, Volume I, Part I, Section 1, Chapters 1 and 2 | H107: MED | I107: NOT_STARTED
A108: 010.06.04.01.11 | B108: 010 | C108: Air Law and ATC Procedures | D108: Explain the relationship between the terms: DA, DH, OCA, OCH, MDA, MDH, MOC, DA/H, OCA/H, and MDA/H. | E108: N | G108: ICAO Doc 8168, Volume I, Part II, Section 5, Chapter 1 General requirements, including Figures II-5-1-2, II-5-1-3. II-5-1-4 | H108: MED | I108: NOT_STARTED
A109: 010.06.04.02.01 | B109: 010 | C109: Air Law and ATC Procedures | D109: Describe how the vertical cross section for each of the five approach segments is broken down into the various areas. | E109: N | G109: ICAO Doc 8168, Volume I, Part II, Section 5, Chapter 1 General requirements | H109: MED | I109: NOT_STARTED
A110: 010.06.04.02.02 | B110: 010 | C110: Air Law and ATC Procedures | D110: State within which area of the cross section the minimum obstacle clearance (MOC) is provided for the whole width of the area. | E110: N | G110: ICAO Doc 8168, Volume I, Part II, Section 1, Chapter 1, 1.3 Areas, 1.3.1 | H110: MED | I110: NOT_STARTED
A111: 010.06.04.02.03 | B111: 010 | C111: Air Law and ATC Procedures | D111: Define the terms ‘IAF’, ‘IF’, ‘FAF’, ‘FAP’, ‘MAPt’ and ‘TP’. | E111: N | G111: ICAO Doc 8168, Volume I, Part I, Section 1 Definitions, abbreviations and acronyms and units of measurement | H111: MED | I111: NOT_STARTED
A112: 010.06.04.02.04 | B112: 010 | C112: Air Law and ATC Procedures | D112: State the accuracy of facilities providing track (VHF omnidirectional radio range (VOR), instrument landing system (ILS), non-directional beacon (NDB)). | E112: Y | G112: ICAO Doc 8168, Volume I, Attachment A, Section 2, Table A-2-1. System use accuracy (2 SD) of facility providing track guidance and facility not providing track guidance | H112: LOW | I112: NOT_STARTED
A113: 010.06.04.02.05 | B113: 010 | C113: Air Law and ATC Procedures | D113: State the optimum descent gradient (preferred for a precision approach) in degrees and per cent. | E113: N | G113: ICAO Doc 8168, Volume I, Part II, Section 5, Chapter 1, 1.10 Descent gradient | H113: MED | I113: NOT_STARTED
...

Sheet S010
A1: 010 Air Law and ATC Procedures
A3: LO_ID | B3: Level | C3: LO_Text | D3: BK_Only | E3: ECQB_2026_Change_Flag | F3: ECQB_2026_Source_Note | G3: Priority | H3: Content_Type_Planned | I3: Repo_Path | J3: Agent_Assigned | K3: Coverage_Status | L3: Last_Updated | M3: Reviewed_By | N3: Notes
A4: 010.01.00.00 | B4: 2 | C4: INTERNATIONAL LAW: CONVENTIONS, AGREEMENTS AND ORGANISATIONS
A5: 010.01.01.00 | B5: 3 | C5: The Convention on International Civil Aviation (Chicago) - ICAO Doc 7300/9 - Convention on the High Seas (Geneva, 29 April 1958)
A6: 010.01.01.01 | B6: 4 | C6: The establishment of the Convention on International Civil Aviation, Chicago, 7 December 1944
A7: 010.01.01.01.01 | B7: 5 | C7: Explain the circumstances that led to the establishment of the Convention on International Civil Aviation, Chicago, 7 December 1944. | D7: Y | F7: ICAO Doc 7300/9 Preamble | G7: LOW | K7: NOT_STARTED
A8: 010.01.01.02 | B8: 4 | C8: Part I - Air navigation
A9: 010.01.01.02.01 | B9: 5 | C9: Recall the general contents of relevant parts of the following chapters: general principles and application of the Convention; flight over territory of Contracting States; nationality of aircraft; international standards and recommended practices (SARPs), especially notification of differences and validity of endorsed certificates and licences. | D9: Y | F9: ICAO Doc 7300/9 Part 1, Articles 1, 2, 3, 4, 5, 6, 7, 8, 9, 10, 11, 12, 16, 17, 18, 19, 20, 37, 38, 39, 40 | G9: LOW | K9: NOT_STARTED
A10: 010.01.01.02.02 | B10: 5 | C10: General principles - Describe the application of the following terms in civil aviation: sovereignty; territory and high seas according to the UN Convention on the High Seas. | D10: Y | F10: Convention on the High Seas (Geneva, 29 April 1958) Articles 1, 2; ICAO Doc 7300/9 Part 1, Articles 1, 2 | G10: LOW | K10: NOT_STARTED
A11: 010.01.01.02.03 | B11: 5 | C11: Explain the following terms and how they apply to international air traffic: right of non-scheduled flight (including the two technical freedoms of the air); scheduled air services; cabotage; landing at customs airports; Rules of the Air; search of aircraft. | D11: N | F11: ICAO Doc 7300/9, Articles 5, 6, 7, 10, 12, 16 | G11: MED | K11: NOT_STARTED
A12: 010.01.01.02.04 | B12: 5 | C12: Explain the duties of Contracting States in relation to: documents carried on board the aircraft: certificate of registration; certificates of airworthiness; licences of personnel; recognition of certificates and licences; cargo restrictions; photographic apparatus. | D12: Y | F12: ICAO Doc 7300/9, Articles 29, 31, 32, 33, 35, 36 | G12: LOW | K12: NOT_STARTED
A13: 010.01.01.03 | B13: 4 | C13: Part II - The International Civil Aviation Organization (ICAO)
A14: 010.01.01.03.01 | B14: 5 | C14: Describe the objectives of ICAO. | D14: Y | F14: ICAO Doc 7300/9, Article 44 | G14: LOW | K14: NOT_STARTED
A15: 010.01.01.03.02 | B15: 5 | C15: Recognise the organisation and duties of the ICAO Assembly, Council and Air Navigation Commission (ANC). | D15: Y | F15: ICAO Doc 7300/9, Articles 48, 49, 50, 54, 56, 57 | G15: LOW | K15: NOT_STARTED
A16: 010.01.01.03.03 | B16: 5 | C16: Describe the annexes to the Convention. | D16: Y | F16: ICAO Doc 7300/9, Articles 54, 90, 94, 95 | G16: LOW | K16: NOT_STARTED
A17: 010.01.02.00 | B17: 3 | C17: Other conventions and agreements
A18: 010.01.02.01 | B18: 4 | C18: The International Air Services Transit Agreement (ICAO Doc 7500)
A19: 010.01.02.01.01 | B19: 5 | C19: Explain the two technical freedoms of the air. | D19: N | F19: ICAO Doc 7500, Art. 1 | G19: MED | K19: NOT_STARTED
A20: 010.01.02.02 | B20: 4 | C20: The International Air Transport Agreement (ICAO Doc 9626)
A21: 010.01.02.02.01 | B21: 5 | C21: Explain the three commercial freedoms of the air. | D21: N | F21: ICAO Doc 9626, Part IV, Chapter 2 'Basic market access' | G21: MED | K21: NOT_STARTED
A22: 010.01.02.03 | B22: 4 | C22: Suppression of Unlawful Acts Against the Safety of Civil Aviation - The Tokyo Convention of 1963
A23: 010.01.02.03.01 | B23: 5 | C23: Describe the measures and actions to be taken by the pilot-in-command (PIC) of an aircraft in order to suppress unlawful acts against the safety of the aircraft. | D23: N | F23: ICAO Doc 8364 — Convention on Offences and Certain Other Acts Committed on Board Aircraft, signed in Tokyo on 14 September 1963, Chapter III 'Powers of the Commander' | G23: MED | K23: NOT_STARTED
A24: 010.01.02.04 | B24: 4 | C24: Intentionally left blank
A25: 010.01.02.05 | B25: 4 | C25: Private international law
A26: 010.01.02.05.01 | B26: 5 | C26: Explain the legal significance of the issue of a passenger ticket or of baggage/cargo documents (that the issue is a form of contract). | D26: N | F26: ICAO Doc 9740 Convention for the Unification of Certain Rules for International Carriage — The Montreal Convention of 1999 | G26: MED | K26: NOT_STARTED
A27: 010.01.02.05.02 | B27: 5 | C27: Describe the consequences for an airline or the PIC when a document of carriage is not issued (that the contract is unaffected). | D27: N | F27: ICAO Doc 9740 Convention for the Unification of Certain Rules for International Carriage — The Montreal Convention of 1999 | G27: MED | K27: NOT_STARTED
A28: 010.01.02.05.03 | B28: 5 | C28: Explain the consequences for an airline operator of Regulation (EC) No 261/2004 on passenger rights in the event of delay, cancellation or denial of boarding. | D28: Y | F28: Regulation (EC) No 261/2004 | G28: LOW | K28: NOT_STARTED
A29: 010.01.02.05.04 | B29: 5 | C29: Explain the liability limit in relation to destruction, loss, damage or delay of baggage. | D29: N | F29: ICAO Doc 9740 Convention for the Unification of Certain Rules for International Carriage - The Montreal Convention of 1999, Chapter III, Art. 17, 19, 22 | G29: MED | K29: NOT_STARTED
A30: 010.01.03.00 | B30: 3 | C30: World organisations
A31: 010.01.03.01 | B31: 4 | C31: The International Air Transport Association (IATA)
A32: 010.01.03.01.01 | B32: 5 | C32: Describe the objectives of IATA. | D32: N | F32: Available via https://www.iata.org/en/about/mission/ | G32: MED | K32: NOT_STARTED
A33: 010.01.04.00 | B33: 3 | C33: European organisations
A34: 010.01.04.01 | B34: 4 | C34: European Union Aviation Safety Agency (EASA) Regulation (EU) 2018/1139 | F34: https://www.easa.europa.eu/en/the-agency/the-agency
A35: 010.01.04.01.01 | B35: 5 | C35: Describe the objectives of EASA. | D35: Y | G35: LOW | K35: NOT_STARTED
A36: 010.01.04.01.02 | B36: 5 | C36: Describe the role of EASA in European civil aviation. | D36: N | G36: MED | K36: NOT_STARTED
A37: 010.01.04.01.03 | B37: 5 | C37: State that the structure of the regulatory material related to EASA involves: hard law (regulations, delegated acts, implementing acts, and implementing rules); soft law (certification specifications, acceptable means of compliance, and guidance material). | D37: N | F37: See https://www.easa.europa.eu/en/light/topics/easas-regulatory-role-increasing-safety-environmental-protection-and-enabling | G37: MED | K37: NOT_STARTED
A38: 010.01.04.01.04 | B38: 5 | C38: State the meaning of the terminology associated with the structure of the regulatory material related to EASA, specifically: regulations, delegated acts, implementing acts, and implementing rules, as applicable until 11 September 2023; and certification specifications, acceptable means of compliance, and guidance material. | D38: N | F38: See https://commission.europa.eu/law/law-making-process/adopting-eu-law/implementing-and-delegated-acts_en and https://www.easa.europa.eu/en/light/topics/easas-regulatory-role-increasing-safety-environmental-protection-and-enabling | G38: MED | K38: NOT_STARTED
A39: 010.01.04.02 | B39: 4 | C39: EUROCONTROL
A40: 010.01.04.02.01 | B40: 5 | C40: Describe the Single European Sky (SES) regulations. | D40: Y | F40: See https://eur-lex.europa.eu/EN/legal-content/summary/single-european-sky-ses.html | G40: LOW | K40: NOT_STARTED
A41: 010.02.00.00 | B41: 2 | C41: AIRWORTHINESS OF AIRCRAFT, AIRCRAFT NATIONALITY AND REGISTRATION MARKS
...

Sheet S021
A1: 021 Aircraft General Knowledge — Airframe, Systems, Powerplant
A3: LO_ID | B3: Level | C3: LO_Text | D3: BK_Only | E3: ECQB_2026_Change_Flag | F3: ECQB_2026_Source_Note | G3: Priority | H3: Content_Type_Planned | I3: Repo_Path | J3: Agent_Assigned | K3: Coverage_Status | L3: Last_Updated | M3: Reviewed_By | N3: Notes
A4: 021.01.00.00 | B4: 2 | C4: SYSTEM DESIGN, LOADS, STRESSES, MAINTENANCE
A5: 021.01.01.00 | B5: 3 | C5: System design
A6: 021.01.01.01 | B6: 4 | C6: Design concepts
A7: 021.01.01.01.01 | B7: 5 | C7: Describe the following structural design philosophy: safe life; fail-safe (multiple load paths); damage-tolerant. | D7: Y | G7: LOW | K7: NOT_STARTED
A8: 021.01.01.01.02 | B8: 5 | C8: Explain the purpose of redundancy in aircraft design. | D8: N | G8: MED | K8: NOT_STARTED
A9: 021.01.01.02 | B9: 4 | C9: Level of certification
A10: 021.01.01.02.01 | B10: 5 | C10: Explain why some systems are duplicated or triplicated. | D10: Y | G10: LOW | K10: NOT_STARTED
A11: 021.01.01.02.02 | B11: 5 | C11: Explain that all aircraft are certified according to specifications determined by the competent authority, and that these certification specifications cover aspects such as design, material quality and build quality. | D11: Y | G11: LOW | K11: NOT_STARTED
A12: 021.01.01.02.03 | B12: 5 | C12: State that the certification specifications for aeroplanes issued by EASA are: CS-23 for Normal, Utility, Aerobatic and Commuter Aeroplanes; CS-25 for Large Aeroplanes. | D12: Y | G12: LOW | K12: NOT_STARTED
A13: 021.01.02.00 | B13: 3 | C13: Loads and stresses
A14: 021.01.02.01 | B14: 4 | C14: Stress, strain and loads
A15: 021.01.02.01.01 | B15: 5 | C15: Explain how stress and strain are always present in an aircraft structure both when parked and during manoeuvring. Remark: Stress is the internal force per unit area inside a structural part as a result of external loads. Strain is the deformation caused by the action of stress on a material. | D15: N | G15: MED | K15: NOT_STARTED
A16: 021.01.02.01.02 | B16: 5 | C16: Describe the following types of loads that an aircraft may be subjected to, when they occur, and how a pilot may affect their magnitude: static loads; dynamic loads; cyclic loads. | D16: N | G16: MED | K16: NOT_STARTED
A17: 021.01.02.01.03 | B17: 5 | C17: Describe the areas typically prone to stress that should be given particular attention during a pre-flight inspection, and highlight the limited visual cues of any deformation that may be evident. | D17: N | G17: MED | K17: NOT_STARTED
A18: 021.01.03.00 | B18: 3 | C18: Fatigue and corrosion
A19: 021.01.03.01 | B19: 4 | C19: Describe and explain fatigue and corrosion
A20: 021.01.03.01.01 | B20: 5 | C20: Describe the effects of corrosion and how it can be visually identified by a pilot during the pre-flight inspection. | D20: N | G20: MED | K20: NOT_STARTED
A21: 021.01.03.01.02 | B21: 5 | C21: Describe the operating environments where the risk of corrosion is increased and how to minimise the effects of the environmental factors. | D21: N | G21: MED | K21: NOT_STARTED
A22: 021.01.03.01.03 | B22: 5 | C22: Explain that aircraft have highly corrosive fluids on board as part of their systems and equipment. | D22: N | G22: MED | K22: NOT_STARTED
A23: 021.01.03.01.04 | B23: 5 | C23: Explain fatigue, how it affects the useful life of an aircraft, and the effect of the following factors on the development of fatigue: corrosion; number of cycles; type of flight manoeuvres; stress level; level and quality of maintenance. | D23: N | G23: MED | K23: NOT_STARTED
A24: 021.01.04.00 | B24: 3 | C24: Intentionally left blank
A25: 021.01.05.00 | B25: 3 | C25: Maintenance
A26: 021.01.05.01 | B26: 4 | C26: Maintenance methods: hard-time and on-condition monitoring
A27: 021.01.05.01.01 | B27: 5 | C27: Explain the following terms: hard-time or fixed-time maintenance; on-condition maintenance; condition monitoring. | D27: N | G27: MED | K27: NOT_STARTED
A28: 021.02.00.00 | B28: 2 | C28: AIRFRAME
A29: 021.02.01.00 | B29: 3 | C29: Attachment methods
A30: 021.02.01.01 | B30: 4 | C30: Attachment methods and detecting the development of faulty attachments
A31: 021.02.01.01.01 | B31: 5 | C31: Describe the following attachment methods used for aircraft parts and components: riveting; welding; bolting; pinning; adhesives (bonding); screwing. | D31: N | G31: MED | K31: NOT_STARTED
A32: 021.02.01.01.02 | B32: 5 | C32: Explain how the development of a faulty attachment between aircraft parts or components can be detected by a pilot during the pre-flight inspection. | D32: N | G32: MED | K32: NOT_STARTED
A33: 021.02.02.00 | B33: 3 | C33: Materials
A34: 021.02.02.01 | B34: 4 | C34: Composite and other materials
A35: 021.02.02.01.01 | B35: 5 | C35: Explain the principle of a composite material, and give examples of typical non-metallic materials used on aircraft: carbon; glass; Kevlar aramid; resin or filler. | D35: Y | G35: LOW | K35: NOT_STARTED
A36: 021.02.02.01.02 | B36: 5 | C36: State the advantages and disadvantages of composite materials compared with metal alloys by considering the following: strength-to-weight ratio; capability to tailor the strength to the direction of the load; stiffness; electrical conductivity (lightning); resistance to fatigue and corrosion; resistance to cost; discovering damage during a pre-flight inspection. | D36: Y | G36: LOW | K36: NOT_STARTED
A37: 021.02.02.01.03 | B37: 5 | C37: State that several types of materials are used on aircraft and that they are chosen based on type of structure or component and the required/desired material properties. | D37: N | G37: MED | K37: NOT_STARTED
A38: 021.02.03.00 | B38: 3 | C38: Aeroplane: wings, tail surfaces and control surfaces
A39: 021.02.03.01 | B39: 4 | C39: Design
A40: 021.02.03.01.01 | B40: 5 | C40: Describe the following types of design and explain their advantages and disadvantages: high-mounted wing; low-mounted wing; low- or mid-set tailplane; T-tail. | D40: N | G40: MED | K40: NOT_STARTED
A41: 021.02.03.02 | B41: 4 | C41: Structural components
...

Sheet S022
A1: 022 Aircraft General Knowledge — Instrumentation
A3: LO_ID | B3: Level | C3: LO_Text | D3: BK_Only | E3: ECQB_2026_Change_Flag | F3: ECQB_2026_Source_Note | G3: Priority | H3: Content_Type_Planned | I3: Repo_Path | J3: Agent_Assigned | K3: Coverage_Status | L3: Last_Updated | M3: Reviewed_By | N3: Notes
A4: 022.01.00.00 | B4: 2 | C4: SENSORS AND INSTRUMENTS
A5: 022.01.01.00 | B5: 3 | C5: Pressure gauge
A6: 022.01.01.01 | B6: 4 | C6: Units for pressure, sensor types, measurements
A7: 022.01.01.01.01 | B7: 5 | C7: Define ‘pressure’, ‘absolute pressure’ and ‘differential pressure’. | D7: Y | G7: LOW | K7: NOT_STARTED
A8: 022.01.01.01.02 | B8: 5 | C8: List the following units used for pressure measurement: Pascal; bar; inches of mercury (in Hg); pounds per square inch (psi). | D8: Y | G8: LOW | K8: NOT_STARTED
A9: 022.01.01.01.03 | B9: 5 | C9: State the relationship between the different units. | D9: Y | G9: LOW | K9: NOT_STARTED
A10: 022.01.01.01.04 | B10: 5 | C10: List and describe the following different types of sensors used according to the pressure to be measured: aneroid capsules; bellows; diaphragms; bourdon tube. | D10: N | G10: MED | K10: NOT_STARTED
A11: 022.01.01.01.05 | B11: 5 | C11: Identify pressure measurements that are applicable to an aircraft: liquid-pressure measurement (fuel, oil, hydraulic); air-pressure measurement (bleed-air systems, air-conditioning systems); engine-pressure measurement manifold pressure (MAP), engine pressure ratio (EPR)). | D11: N | G11: MED | K11: NOT_STARTED
A12: 022.01.01.01.06 | B12: 5 | C12: Identify and read pressure measurement indications both for engine indications and other systems. | D12: N | G12: MED | K12: NOT_STARTED
A13: 022.01.01.01.07 | B13: 5 | C13: Explain the implications of the following pressure measurement errors both for engine indications and other systems: loss of pressure sensing; incorrect pressure indications. | D13: N | G13: MED | K13: NOT_STARTED
A14: 022.01.02.00 | B14: 3 | C14: Temperature sensing
A15: 022.01.02.01 | B15: 4 | C15: Units for temperature, measurements
A16: 022.01.02.01.01 | B16: 5 | C16: Explain temperature. | D16: Y | G16: LOW | K16: NOT_STARTED
A17: 022.01.02.01.02 | B17: 5 | C17: List the following units that can be used for temperature measurement: Kelvin; Celsius; Fahrenheit. | D17: Y | G17: LOW | K17: NOT_STARTED
A18: 022.01.02.01.03 | B18: 5 | C18: State the relationship between these units and convert between them. | D18: Y | G18: LOW | K18: NOT_STARTED
A19: 022.01.02.01.04 | B19: 5 | C19: Identify temperature measurements that are applicable to an aircraft: gas temperature measurement (ambient air, bleed-air systems, air-conditioning systems, air inlet, exhaust gas, gas turbine outlets); liquid-temperature measurement (fuel, oil, hydraulic); component-temperature measurement (generator, transformer rectifier unit (TRU), pumps (fuel, hydraulic), power transfer unit (PTU). | D19: N | G19: MED | K19: NOT_STARTED
A20: 022.01.02.01.05 | B20: 5 | C20: Identify and read temperature measurement indications for both engine indications and other systems. | D20: N | G20: MED | K20: NOT_STARTED
A21: 022.01.03.00 | B21: 3 | C21: Fuel gauge
A22: 022.01.03.01 | B22: 4 | C22: Units for fuel, measurements, fuel gauges
A23: 022.01.03.01.01 | B23: 5 | C23: State that the quantity of fuel can be measured by volume or mass. | D23: N | G23: MED | K23: NOT_STARTED
A24: 022.01.03.01.02 | B24: 5 | C24: List the following units used for fuel quantity: kilogramme; pound; litres; gallons (US and imperial). | D24: N | G24: MED | K24: NOT_STARTED
A25: 022.01.03.01.03 | B25: 5 | C25: Convert between the various units. | D25: N | G25: MED | K25: NOT_STARTED
A26: 022.01.03.01.04 | B26: 5 | C26: Explain the parameters that can affect the measurement of the volume or mass of the fuel in a fuel tank: temperature; aircraft accelerations and attitudes; and explain how the fuel-gauge system design compensates for these changes. | D26: N | G26: MED | K26: NOT_STARTED
A27: 022.01.03.01.05 | B27: 5 | C27: Describe and explain the operating principles of the following types of fuel gauges: float system; capacitance-type of fuel-gauge system. ultrasound-type of fuel-gauge system: to be introduced at a later date. | D27: N | G27: MED | K27: NOT_STARTED
A28: 022.01.03.01.06 | B28: 5 | C28: Describe and complete a typical post-refuelling procedure for a pilot: recording the volume that was filled; converting to the appropriate unit used by the aircraft fuel gauge(s) to compare the actual indicated fuel content to the calculated fuel content; assess appropriate action if the numbers does not compare. | D28: N | G28: MED | K28: NOT_STARTED
A29: 022.01.04.00 | B29: 3 | C29: Fuel flowmeters
A30: 022.01.04.01 | B30: 4 | C30: Fuel flow, units for fuel flow, total fuel consumption
A31: 022.01.04.01.01 | B31: 5 | C31: Define ‘fuel flow’ and where it is measured. | D31: N | G31: MED | K31: NOT_STARTED
A32: 022.01.04.01.02 | B32: 5 | C32: State that fuel flow may be measured by volume or mass per unit of time. | D32: N | G32: MED | K32: NOT_STARTED
A33: 022.01.04.01.03 | B33: 5 | C33: List the following units used for fuel flow when measured by mass per hour: kilogrammes/hour; pounds/hour. | D33: N | G33: MED | K33: NOT_STARTED
A34: 022.01.04.01.04 | B34: 5 | C34: List the following units used for fuel flow when measured by volume per hour: litres/hour; imperial gallons/hour; US gallons/hour. | D34: N | G34: MED | K34: NOT_STARTED
A35: 022.01.04.01.05 | B35: 5 | C35: Explain how total fuel consumption is obtained. | D35: N | G35: MED | K35: NOT_STARTED
A36: 022.01.05.00 | B36: 3 | C36: Tachometer
A37: 022.01.05.01 | B37: 4 | C37: Types, operating principles, units for engine speed
A38: 022.01.05.01.01 | B38: 5 | C38: List the following types of tachometers, describe their basic operating principle and give examples of use: mechanical (rotating magnet); electrical (three-phase tacho-generator); electronic (impulse measurement with speed probe and phonic wheel); and describe the operating principle of each type. | D38: Y | G38: LOW | K38: NOT_STARTED
A39: 022.01.05.01.02 | B39: 5 | C39: Explain the typical units for engine speed: rpm for piston-engine aircraft; percentage for turbine-engine aircraft. | D39: N | G39: MED | K39: NOT_STARTED
A40: 022.01.05.01.03 | B40: 5 | C40: Explain that some types of rpm indicators require electrical power to provide an indication. | D40: N | G40: MED | K40: NOT_STARTED
A41: 022.01.06.00 | B41: 3 | C41: Thrust measurement
...

Sheet S031
A1: 031 Mass and Balance
A3: LO_ID | B3: Level | C3: LO_Text | D3: BK_Only | E3: ECQB_2026_Change_Flag | F3: ECQB_2026_Source_Note | G3: Priority | H3: Content_Type_Planned | I3: Repo_Path | J3: Agent_Assigned | K3: Coverage_Status | L3: Last_Updated | M3: Reviewed_By | N3: Notes
A4: 031.01.00.00 | B4: 2 | C4: PURPOSE OF MASS-AND-BALANCE CONSIDERATIONS
A5: 031.01.01.00 | B5: 3 | C5: Mass limitations
A6: 031.01.01.01 | B6: 4 | C6: Importance with regard to structural limitations
A7: 031.01.01.01.01 | B7: 5 | C7: Describe the relationship between aircraft mass and structural stress. Remark: See also Subject 021 01 01 00. | D7: Y | G7: LOW | K7: NOT_STARTED
A8: 031.01.01.01.02 | B8: 5 | C8: Describe why mass must be limited to ensure adequate margins of strength. | D8: Y | G8: LOW | K8: NOT_STARTED
A9: 031.01.01.02 | B9: 4 | C9: Importance with regard to performance Remark: See also Subjects 032/034 and 081/082.
A10: 031.01.01.02.01 | B10: 5 | C10: Describe the relationship between aircraft mass and aircraft performance. | D10: N | G10: MED | K10: NOT_STARTED
A11: 031.01.01.02.02 | B11: 5 | C11: Describe why aircraft mass must be limited to ensure adequate aircraft performance. | D11: Y | G11: LOW | K11: NOT_STARTED
A12: 031.01.02.00 | B12: 3 | C12: Centre-of-gravity (CG) limitations
A13: 031.01.02.01 | B13: 4 | C13: Importance with regard to stability and controllability Remark: See also Subjects 081/082.
A14: 031.01.02.01.01 | B14: 5 | C14: Describe the relationship between CG position and stability/controllability of the aircraft. | D14: Y | G14: LOW | K14: NOT_STARTED
A15: 031.01.02.01.02 | B15: 5 | C15: Describe the consequences if CG is in front of the forward limit. | D15: N | G15: MED | K15: NOT_STARTED
A16: 031.01.02.01.03 | B16: 5 | C16: Describe the consequences if CG is behind the aft limit. | D16: N | G16: MED | K16: NOT_STARTED
A17: 031.01.02.02 | B17: 4 | C17: Importance with regard to performance Remark: See also Subjects 032/034 and 081/082.
A18: 031.01.02.02.01 | B18: 5 | C18: Describe the relationship between CG position and aircraft performance. | D18: Y | G18: LOW | K18: NOT_STARTED
A19: 031.01.02.02.02 | B19: 5 | C19: Describe the effects of CG position on performance parameters (speeds, altitude, endurance and range). | D19: N | G19: MED | K19: NOT_STARTED
A20: 031.02.00.00 | B20: 2 | C20: LOADING
A21: 031.02.01.00 | B21: 3 | C21: Terminology
A22: 031.02.01.01 | B22: 4 | C22: Mass terms
A23: 031.02.01.01.01 | B23: 5 | C23: Define the following mass terms: basic empty mass; dry operating mass; operating mass; take-off mass; landing mass; ramp/taxi mass; in-flight mass (gross mass); zero fuel mass. | D23: Y | E23: Fuel/energy scheme (basic, RCF 3%, isolated aerodrome, extra/discretionary fuel) | G23: HIGH | K23: NOT_STARTED
A24: 031.02.01.02 | B24: 4 | C24: Load terms (including fuel terms) Remark: See also Subject 033.
A25: 031.02.01.02.01 | B25: 5 | C25: Define the following load terms: payload/traffic load; block fuel; taxi fuel; take-off fuel; trip fuel; reserve fuel (contingency, alternate, final reserve and additional fuel); extra fuel. | D25: Y | E25: Fuel/energy scheme (basic, RCF 3%, isolated aerodrome, extra/discretionary fuel) | G25: HIGH | K25: NOT_STARTED
A26: 031.02.01.02.02 | B26: 5 | C26: Explain the relationship between the various load-and-mass components listed in 031 02 01 01 and 031 02 01 02. | D26: N | G26: MED | K26: NOT_STARTED
A27: 031.02.01.02.03 | B27: 5 | C27: Calculate the mass of particular components from other given components. | D27: N | G27: MED | K27: NOT_STARTED
A28: 031.02.01.02.04 | B28: 5 | C28: Convert fuel mass, fuel volume and fuel density given in different units used in aviation. | D28: N | E28: Fuel/energy scheme (basic, RCF 3%, isolated aerodrome, extra/discretionary fuel) | G28: HIGH | K28: NOT_STARTED
A29: 031.02.02.00 | B29: 3 | C29: Mass limits
A30: 031.02.02.01 | B30: 4 | C30: Structural limitations
A31: 031.02.02.01.01 | B31: 5 | C31: Define the maximum zero fuel mass. | D31: Y | E31: Fuel/energy scheme (basic, RCF 3%, isolated aerodrome, extra/discretionary fuel) | G31: HIGH | K31: NOT_STARTED
A32: 031.02.02.01.02 | B32: 5 | C32: Define the maximum ramp/taxi mass. | D32: Y | G32: LOW | K32: NOT_STARTED
A33: 031.02.02.01.03 | B33: 5 | C33: Define the maximum take-off mass. | D33: Y | G33: LOW | K33: NOT_STARTED
A34: 031.02.02.01.05 | B34: 5 | C34: Define the maximum landing mass. | D34: Y | G34: LOW | K34: NOT_STARTED
A35: 031.02.02.02 | B35: 4 | C35: Performance and regulated limitations
A36: 031.02.02.02.01 | B36: 5 | C36: Describe the following performance and regulated mass limitations: performance-limited take-off mass; performance-limited landing mass; regulated take-off mass; regulated landing mass. | D36: N | G36: MED | K36: NOT_STARTED
A37: 031.02.02.03 | B37: 4 | C37: Cargo compartment limitations
A38: 031.02.02.03.01 | B38: 5 | C38: Describe the maximum floor load (maximum load per unit of area). | D38: Y | G38: LOW | K38: NOT_STARTED
A39: 031.02.02.03.02 | B39: 5 | C39: Describe the maximum running load (maximum load per unit of fuselage length). | D39: Y | G39: LOW | K39: NOT_STARTED
A40: 031.02.03.00 | B40: 3 | C40: Mass calculations
A41: 031.02.03.01 | B41: 4 | C41: Maximum masses for take-off and landing
...

Sheet S032
A1: 032 Performance — Aeroplanes
A3: LO_ID | B3: Level | C3: LO_Text | D3: BK_Only | E3: ECQB_2026_Change_Flag | F3: ECQB_2026_Source_Note | G3: Priority | H3: Content_Type_Planned | I3: Repo_Path | J3: Agent_Assigned | K3: Coverage_Status | L3: Last_Updated | M3: Reviewed_By | N3: Notes
A4: 032.01.00.00 | B4: 2 | C4: GENERAL
A5: 032.01.01.00 | B5: 3 | C5: Performance legislation
A6: 032.01.01.01 | B6: 4 | C6: Applicability of airworthiness requirements of CS-23 and CS-25
A7: 032.01.01.01.01 | B7: 5 | C7: Describe the application of certification specification (CSs) with regard to the different kinds of aeroplanes. | D7: Y | G7: LOW | K7: NOT_STARTED
A8: 032.01.01.01.02 | B8: 5 | C8: Describe the general differences between aeroplanes certified according to CS-23 and CS-25. | D8: Y | G8: LOW | K8: NOT_STARTED
A9: 032.01.01.02 | B9: 4 | C9: Operational regulations and safety
A10: 032.01.01.02.01 | B10: 5 | C10: Describe the basic concept that the applicable operational requirements differ depending on aeroplane performance. | D10: Y | G10: LOW | K10: NOT_STARTED
A11: 032.01.01.02.02 | B11: 5 | C11: Describe the performance classes for commercial air transport according to the applicable operational requirements. | D11: N | G11: MED | K11: NOT_STARTED
A12: 032.01.01.03 | B12: 4 | C12: Performance and safety
A13: 032.01.01.03.01 | B13: 5 | C13: State that aeroplane performance required for commercial air transport may limit the weight of a dispatched aeroplane in order to achieve a sufficient level of safety. | D13: Y | G13: LOW | K13: NOT_STARTED
A14: 032.01.01.03.02 | B14: 5 | C14: Describe that the minimum level of safety required for commercial air transport is ensured through the combination of airworthiness requirements and operational limitations, i.e. the more stringent airworthiness requirements of CS-25 enable a wider range of operating conditions for these aeroplanes. | D14: Y | G14: LOW | K14: NOT_STARTED
A15: 032.01.01.04 | B15: 4 | C15: Performance definitions and safety factors
A16: 032.01.01.04.01 | B16: 5 | C16: Describe measured performance and explain how it is determined. | D16: Y | G16: LOW | K16: NOT_STARTED
A17: 032.01.01.04.02 | B17: 5 | C17: Describe gross performance. | D17: N | G17: MED | K17: NOT_STARTED
A18: 032.01.01.04.03 | B18: 5 | C18: Describe net performance and safety factors. | D18: N | G18: MED | K18: NOT_STARTED
A19: 032.01.01.04.04 | B19: 5 | C19: Describe that the size of a safety factor depends on the likelihood of the event and the range of the measured performance data. | D19: Y | G19: LOW | K19: NOT_STARTED
A20: 032.01.01.04.05 | B20: 5 | C20: Describe the relationship between net and gross take-off and landing distances, and net and gross climb and descent gradients. | D20: N | G20: MED | K20: NOT_STARTED
A21: 032.01.02.00 | B21: 3 | C21: General performance theory
A22: 032.01.02.01 | B22: 4 | C22: Intentionally left blank
A23: 032.01.02.02 | B23: 4 | C23: Definitions and terms
A24: 032.01.02.02.01 | B24: 5 | C24: Define the terms ‘climb angle’ and ‘climb gradient’. | D24: Y | G24: LOW | K24: NOT_STARTED
A25: 032.01.02.02.02 | B25: 5 | C25: Define the terms ‘flight-path angle’ and ‘flight-path gradient’. | D25: Y | G25: LOW | K25: NOT_STARTED
A26: 032.01.02.02.03 | B26: 5 | C26: Define the terms ‘descent angle’ and ‘descent gradient’. | D26: Y | G26: LOW | K26: NOT_STARTED
A27: 032.01.02.02.04 | B27: 5 | C27: Explain the difference between climb/descent angle and flight-path angle. | D27: Y | G27: LOW | K27: NOT_STARTED
A28: 032.01.02.02.05 | B28: 5 | C28: Define ‘absolute ceiling’. | D28: Y | G28: LOW | K28: NOT_STARTED
A29: 032.01.02.02.06 | B29: 5 | C29: Describe ‘clearway’ and ‘stopway’ according to CS-Definitions. | D29: N | G29: MED | K29: NOT_STARTED
A30: 032.01.02.02.07 | B30: 5 | C30: Describe: take-off run available (TORA); take-off distance available (TODA); accelerate-stop distance available (ASDA); and determine each from given data or appropriate aerodrome charts. | D30: N | G30: MED | K30: NOT_STARTED
A31: 032.01.02.02.08 | B31: 5 | C31: Describe ‘screen height’ including its various values. | D31: N | G31: MED | K31: NOT_STARTED
A32: 032.01.02.02.09 | B32: 5 | C32: Define the terms ‘range’ and ‘endurance’. | D32: Y | G32: LOW | K32: NOT_STARTED
A33: 032.01.02.02.10 | B33: 5 | C33: Define an aeroplane’s ‘specific range’ (SR) in terms of nautical air miles (NAM) per unit of fuel, and ‘specific range over the ground’ (SRG) in terms of nautical ground miles (NGM) per unit of fuel. | D33: N | E33: Fuel/energy scheme alignment | G33: HIGH | K33: NOT_STARTED
A34: 032.01.02.02.11 | B34: 5 | C34: Define the power available and power required. | D34: N | G34: MED | K34: NOT_STARTED
A35: 032.01.02.03 | B35: 4 | C35: Variables influencing performance
A36: 032.01.02.03.01 | B36: 5 | C36: Name the following factors that affect aeroplane performance: pressure altitude and temperature, wind, aeroplane weight, aeroplane configuration, aeroplane anti-skid status, aeroplane centre of gravity (CG), aerodrome runway surface, and aerodrome runway slope. | D36: Y | G36: LOW | K36: NOT_STARTED
A37: 032.01.02.03.02 | B37: 5 | C37: Describe how, for different density altitudes, the thrust and power available vary with speed for a propeller-driven aeroplane. | D37: Y | G37: LOW | K37: NOT_STARTED
A38: 032.01.02.03.03 | B38: 5 | C38: Describe how, for different density altitudes, the thrust and power available vary with speed for a turbojet aeroplane. | D38: Y | G38: LOW | K38: NOT_STARTED
A39: 032.01.02.03.04 | B39: 5 | C39: Describe how, for different density altitudes, the drag and power required vary with indicated airspeeds (IAS) and true airspeeds (TAS). | D39: N | G39: MED | K39: NOT_STARTED
A40: 032.01.02.03.05 | B40: 5 | C40: Describe how, for different aeroplane weights and configurations, the drag and power required vary with IAS and TAS. | D40: N | G40: MED | K40: NOT_STARTED
A41: 032.01.03.00 | B41: 3 | C41: Level flight, range and endurance
...

Sheet S033
A1: 033 Flight Planning and Monitoring
A3: LO_ID | B3: Level | C3: LO_Text | D3: BK_Only | E3: ECQB_2026_Change_Flag | F3: ECQB_2026_Source_Note | G3: Priority | H3: Content_Type_Planned | I3: Repo_Path | J3: Agent_Assigned | K3: Coverage_Status | L3: Last_Updated | M3: Reviewed_By | N3: Notes
A4: 033.01.00.00 | B4: 2 | C4: FLIGHT PLANNING FOR VFR FLIGHTS Remark: Using the GSPRM VFR charts.
A5: 033.01.01.00 | B5: 3 | C5: VFR navigation plan
A6: 033.01.01.01 | B6: 4 | C6: Airspace, communication, visual and radio-navigation data from VFR charts
A7: 033.01.01.01.01 | B7: 5 | C7: Select routes taking the following criteria into account: classification of airspace; restricted areas; VFR semicircular rules; visually conspicuous points; radio-navigation aids. | D7: N | G7: MED | K7: NOT_STARTED
A8: 033.01.01.01.02 | B8: 5 | C8: Find the frequencies or identifiers of radio-navigation aids from charts. | D8: N | G8: MED | K8: NOT_STARTED
A9: 033.01.01.01.03 | B9: 5 | C9: Find the communication frequencies and call signs for the following: control agencies and service facilities; flight information service (FIS); weather information stations; automatic terminal information service (ATIS). | D9: N | G9: MED | K9: NOT_STARTED
A10: 033.01.01.02 | B10: 4 | C10: Planning courses, distances and cruising levels with VFR charts
A11: 033.01.01.02.01 | B11: 5 | C11: Choose visual waypoints in accordance with specified criteria (large, unique, contrast, vertical extent, etc.). | D11: N | G11: MED | K11: NOT_STARTED
A12: 033.01.01.02.02 | B12: 5 | C12: Measure courses and distances from a VFR chart. | D12: N | G12: MED | K12: NOT_STARTED
A13: 033.01.01.02.03 | B13: 5 | C13: Find the highest obstacle within a given distance on either side of the course. | D13: N | G13: MED | K13: NOT_STARTED
A14: 033.01.01.02.04 | B14: 5 | C14: Find the following data from a VFR chart and transfer them to a navigation plan: waypoints or turning points; distances; true/magnetic courses. | D14: N | G14: MED | K14: NOT_STARTED
A15: 033.01.01.02.05 | B15: 5 | C15: Calculate the minimum pressure altitude with a given obstacle clearance or true altitude from a given altitude or pressure altitude from minimum grid-area altitude using outside air temperature (OAT) and QNH. | D15: N | G15: MED | K15: NOT_STARTED
A16: 033.01.01.02.06 | B16: 5 | C16: Calculate the vertical or horizontal distance and time to climb or descend to/from a given level or altitude with given data. | D16: N | G16: MED | K16: NOT_STARTED
A17: 033.01.01.02.07 | B17: 5 | C17: Explain how to determine the position of a significant VFR point for insertion into a global navigation satellite system (GNSS) flight plan, using the distance and bearing from an existing significant point and using coordinates. | D17: N | G17: MED | K17: NOT_STARTED
A18: 033.01.01.03 | B18: 4 | C18: Aerodrome charts and aerodrome directory
A19: 033.01.01.03.01 | B19: 5 | C19: Explain the reasons for studying the visual departure procedures and the available approach procedures. | D19: Y | G19: LOW | K19: NOT_STARTED
A20: 033.01.01.03.02 | B20: 5 | C20: Find all visual procedures which can be expected at the departure, destination and alternate aerodromes. | D20: N | E20: Fuel/energy scheme: basic + RCF 3% + isolated aerodrome + revised extra/discretionary fuel | G20: HIGH | K20: NOT_STARTED
A21: 033.01.01.03.03 | B21: 5 | C21: Find all relevant aeronautical and regulatory information required for VFR flight planning from the aerodrome charts or aerodrome directory. | D21: N | G21: MED | K21: NOT_STARTED
A22: 033.01.01.04 | B22: 4 | C22: Intentionally left blank
A23: 033.01.01.05 | B23: 4 | C23: Completion of navigation plan
A24: 033.01.01.05.01 | B24: 5 | C24: Calculate the true airspeed (TAS) from given aircraft performance data, altitude and OAT. | D24: N | G24: MED | K24: NOT_STARTED
A25: 033.01.01.05.02 | B25: 5 | C25: Calculate wind correction angles (WCAs), drift and ground speeds (GS). | D25: N | G25: MED | K25: NOT_STARTED
A26: 033.01.01.05.03 | B26: 5 | C26: Calculate individual and accumulated times for each leg to destination and alternate aerodromes. | D26: N | E26: Fuel/energy scheme: basic + RCF 3% + isolated aerodrome + revised extra/discretionary fuel | G26: HIGH | K26: NOT_STARTED
A27: 033.02.00.00 | B27: 2 | C27: FLIGHT PLANNING FOR IFR FLIGHTS Remark: Using the GSPRM IFR charts.
A28: 033.02.01.00 | B28: 3 | C28: IFR navigation plan
A29: 033.02.01.01 | B29: 4 | C29: Air traffic service (ATS) routes
A30: 033.02.01.01.01 | B30: 5 | C30: Identify suitable routings by identifying all relevant aeronautical and regulatory information (including information published in the national aeronautical information publication (AIP)) required for IFR flight planning. | D30: N | G30: MED | K30: NOT_STARTED
A31: 033.02.01.01.02 | B31: 5 | C31: Identify and describe ATS routes (conventional, area navigation (RNAV), required navigation performance (RNP), conditional routes (CDRs), and direct routes). | D31: N | G31: MED | K31: NOT_STARTED
A32: 033.02.01.02 | B32: 4 | C32: Courses and distances from en-route charts
A33: 033.02.01.02.01 | B33: 5 | C33: Determine courses and distances. | D33: N | G33: MED | K33: NOT_STARTED
A34: 033.02.01.02.02 | B34: 5 | C34: Determine bearings and distances of waypoints from radio-navigation aids. | D34: N | G34: MED | K34: NOT_STARTED
A35: 033.02.01.03 | B35: 4 | C35: Altitudes
A36: 033.02.01.03.01 | B36: 5 | C36: Define the following altitudes: minimum en-route altitude (MEA); minimum obstacle clearance altitude (MOCA); minimum sector altitude (MSA); minimum off-route altitude (MORA); grid minimum off-route altitude (Grid MORA); maximum authorised altitude (MAA); minimum crossing altitude (MCA); minimum holding altitude (MHA). | D36: N | G36: MED | K36: NOT_STARTED
A37: 033.02.01.03.02 | B37: 5 | C37: Extract the following altitudes from the chart(s): MEA; MOCA; MSA; MORA; Grid MORA; MAA; MCA; MHA. | D37: N | G37: MED | K37: NOT_STARTED
A38: 033.02.01.03.03 | B38: 5 | C38: State who is responsible for terrain separation during IFR flight inside and outside controlled airspace. | D38: N | G38: MED | K38: NOT_STARTED
A39: 033.02.01.03.04 | B39: 5 | C39: State the minimum obstacle clearance requirements for en-route IFR flight inside and outside controlled airspace. | D39: N | G39: MED | K39: NOT_STARTED
A40: 033.02.01.03.05 | B40: 5 | C40: State when a temperature error correction must be applied by either the pilot or ATC. | D40: N | G40: MED | K40: NOT_STARTED
A41: 033.02.01.03.06 | B41: 5 | C41: Identify and explain the use of minimum radar vectoring altitudes. | D41: N | G41: MED | K41: NOT_STARTED
...

Sheet S040
A1: 040 Human Performance and Limitations
